[2024-12-17T18:00:29.834+0000] {__init__.py:54} DEBUG - Loading core task runner: StandardTaskRunner
[2024-12-17T18:00:29.860+0000] {base_task_runner.py:73} DEBUG - Planning to run as the  user
[2024-12-17T18:00:29.867+0000] {local_task_job_runner.py:123} INFO - ::group::Pre task execution logs
[2024-12-17T18:00:29.890+0000] {taskinstance.py:2625} DEBUG - <TaskInstance: tiktok_dag.fetch_all_user_data manual__2024-12-17T18:00:24.493983+00:00 [queued]> dependency 'Task Instance State' PASSED: True, Task state queued was valid.
[2024-12-17T18:00:29.891+0000] {taskinstance.py:2625} DEBUG - <TaskInstance: tiktok_dag.fetch_all_user_data manual__2024-12-17T18:00:24.493983+00:00 [queued]> dependency 'Task Instance Not Running' PASSED: True, Task is not in running state.
[2024-12-17T18:00:29.892+0000] {taskinstance.py:2625} DEBUG - <TaskInstance: tiktok_dag.fetch_all_user_data manual__2024-12-17T18:00:24.493983+00:00 [queued]> dependency 'Not In Retry Period' PASSED: True, The task instance was not marked for retrying.
[2024-12-17T18:00:29.892+0000] {taskinstance.py:2625} DEBUG - <TaskInstance: tiktok_dag.fetch_all_user_data manual__2024-12-17T18:00:24.493983+00:00 [queued]> dependency 'Previous Dagrun State' PASSED: True, The task did not have depends_on_past set.
[2024-12-17T18:00:29.893+0000] {taskinstance.py:2613} INFO - Dependencies all met for dep_context=non-requeueable deps ti=<TaskInstance: tiktok_dag.fetch_all_user_data manual__2024-12-17T18:00:24.493983+00:00 [queued]>
[2024-12-17T18:00:29.896+0000] {taskinstance.py:2625} DEBUG - <TaskInstance: tiktok_dag.fetch_all_user_data manual__2024-12-17T18:00:24.493983+00:00 [queued]> dependency 'Not In Retry Period' PASSED: True, The task instance was not marked for retrying.
[2024-12-17T18:00:29.897+0000] {taskinstance.py:2625} DEBUG - <TaskInstance: tiktok_dag.fetch_all_user_data manual__2024-12-17T18:00:24.493983+00:00 [queued]> dependency 'Previous Dagrun State' PASSED: True, The task did not have depends_on_past set.
[2024-12-17T18:00:29.897+0000] {taskinstance.py:2625} DEBUG - <TaskInstance: tiktok_dag.fetch_all_user_data manual__2024-12-17T18:00:24.493983+00:00 [queued]> dependency 'Task Concurrency' PASSED: True, Task concurrency is not set.
[2024-12-17T18:00:29.903+0000] {taskinstance.py:2625} DEBUG - <TaskInstance: tiktok_dag.fetch_all_user_data manual__2024-12-17T18:00:24.493983+00:00 [queued]> dependency 'Pool Slots Available' PASSED: True, There are enough open slots in default_pool to execute the task
[2024-12-17T18:00:29.908+0000] {taskinstance.py:2613} INFO - Dependencies all met for dep_context=requeueable deps ti=<TaskInstance: tiktok_dag.fetch_all_user_data manual__2024-12-17T18:00:24.493983+00:00 [queued]>
[2024-12-17T18:00:29.908+0000] {taskinstance.py:2866} INFO - Starting attempt 1 of 2
[2024-12-17T18:00:29.927+0000] {taskinstance.py:2889} INFO - Executing <Task(PythonOperator): fetch_all_user_data> on 2024-12-17 18:00:24.493983+00:00
[2024-12-17T18:00:29.938+0000] {logging_mixin.py:190} WARNING - /home/***/.local/lib/python3.12/site-packages/***/task/task_runner/standard_task_runner.py:70 DeprecationWarning: This process (pid=2305) is multi-threaded, use of fork() may lead to deadlocks in the child.
[2024-12-17T18:00:29.941+0000] {standard_task_runner.py:72} INFO - Started process 2307 to run task
[2024-12-17T18:00:29.938+0000] {standard_task_runner.py:104} INFO - Running: ['***', 'tasks', 'run', 'tiktok_dag', 'fetch_all_user_data', 'manual__2024-12-17T18:00:24.493983+00:00', '--job-id', '56', '--raw', '--subdir', 'DAGS_FOLDER/tiktok_dag.py', '--cfg-path', '/tmp/tmpatyvqok7']
[2024-12-17T18:00:29.942+0000] {standard_task_runner.py:105} INFO - Job 56: Subtask fetch_all_user_data
[2024-12-17T18:00:29.943+0000] {cli_action_loggers.py:79} DEBUG - Calling callbacks: [<function default_action_log at 0x7f8722155da0>]
[2024-12-17T18:00:30.003+0000] {task_command.py:467} INFO - Running <TaskInstance: tiktok_dag.fetch_all_user_data manual__2024-12-17T18:00:24.493983+00:00 [running]> on host 8ee198177aea
[2024-12-17T18:00:30.066+0000] {taskinstance.py:2384} DEBUG - Clearing XCom data
[2024-12-17T18:00:30.081+0000] {retries.py:95} DEBUG - Running RenderedTaskInstanceFields.write with retries. Try 1 of 3
[2024-12-17T18:00:30.107+0000] {retries.py:95} DEBUG - Running RenderedTaskInstanceFields._do_delete_old_records with retries. Try 1 of 3
[2024-12-17T18:00:30.119+0000] {taskinstance.py:3132} INFO - Exporting env vars: AIRFLOW_CTX_DAG_OWNER='***' AIRFLOW_CTX_DAG_ID='tiktok_dag' AIRFLOW_CTX_TASK_ID='fetch_all_user_data' AIRFLOW_CTX_EXECUTION_DATE='2024-12-17T18:00:24.493983+00:00' AIRFLOW_CTX_TRY_NUMBER='1' AIRFLOW_CTX_DAG_RUN_ID='manual__2024-12-17T18:00:24.493983+00:00'
[2024-12-17T18:00:30.120+0000] {__init__.py:115} DEBUG - Preparing lineage inlets and outlets
[2024-12-17T18:00:30.121+0000] {__init__.py:154} DEBUG - inlets: [], outlets: []
[2024-12-17T18:00:30.123+0000] {taskinstance.py:731} INFO - ::endgroup::
[2024-12-17T18:00:30.151+0000] {tiktok_dag.py:51} INFO - Fetching data for all usernames...
[2024-12-17T18:00:30.163+0000] {tiktok_dag.py:53} INFO - Usernames pulled from XCom: ['mrbeast', 'jadeanna', 'feyenoord']
[2024-12-17T18:00:30.163+0000] {tiktok_dag.py:59} INFO - Fetching data for username: mrbeast
[2024-12-17T18:00:30.164+0000] {tiktok_etl.py:134} INFO - Now in function tiktok_get_user_info, getting mrbeast
[2024-12-17T18:00:30.164+0000] {tiktok_etl.py:141} INFO - Requesting TikTok API with URL: https://open.tiktokapis.com/v2/research/user/info/, Headers: {'Authorization': 'Bearer clt.2.2FPqi0MGZIXZZ3clzQTNgyPDqxrcckxt1d-KDYDU4OFr7UMQYh3pHDTym9rRjGwCNZCJ-Oh2yVQv7VAjzbHf8w*0', 'Content-Type': 'application/json'}, Body: {'username': 'mrbeast'}
[2024-12-17T18:00:30.168+0000] {connectionpool.py:1051} DEBUG - Starting new HTTPS connection (1): open.tiktokapis.com:443
[2024-12-17T18:00:30.576+0000] {connectionpool.py:546} DEBUG - https://open.tiktokapis.com:443 "POST /v2/research/user/info/?fields=display_name%2Cbio_description%2Cis_verified%2Cfollower_count%2Cfollowing_count%2Clikes_count%2Cvideo_count HTTP/11" 401 166
[2024-12-17T18:00:30.577+0000] {tiktok_etl.py:144} INFO - Call is done...
[2024-12-17T18:00:30.578+0000] {tiktok_etl.py:164} INFO - TIKTOK request requests.exceptions.HTTPError
[2024-12-17T18:00:30.579+0000] {tiktok_etl.py:166} INFO - HTTP error occurred: 401 Client Error: Unauthorized for url: https://open.tiktokapis.com/v2/research/user/info/?fields=display_name%2Cbio_description%2Cis_verified%2Cfollower_count%2Cfollowing_count%2Clikes_count%2Cvideo_count
Traceback (most recent call last):
  File "/opt/airflow/dags/tiktok_etl.py", line 147, in tiktok_get_user_info
    response.raise_for_status()  # This will raise an exception for 4xx/5xx errors
    ^^^^^^^^^^^^^^^^^^^^^^^^^^^
  File "/home/airflow/.local/lib/python3.12/site-packages/requests/models.py", line 1024, in raise_for_status
    raise HTTPError(http_error_msg, response=self)
requests.exceptions.HTTPError: 401 Client Error: Unauthorized for url: https://open.tiktokapis.com/v2/research/user/info/?fields=display_name%2Cbio_description%2Cis_verified%2Cfollower_count%2Cfollowing_count%2Clikes_count%2Cvideo_count
[2024-12-17T18:00:30.586+0000] {tiktok_etl.py:167} INFO - Status Code: 401
Traceback (most recent call last):
  File "/opt/airflow/dags/tiktok_etl.py", line 147, in tiktok_get_user_info
    response.raise_for_status()  # This will raise an exception for 4xx/5xx errors
    ^^^^^^^^^^^^^^^^^^^^^^^^^^^
  File "/home/airflow/.local/lib/python3.12/site-packages/requests/models.py", line 1024, in raise_for_status
    raise HTTPError(http_error_msg, response=self)
requests.exceptions.HTTPError: 401 Client Error: Unauthorized for url: https://open.tiktokapis.com/v2/research/user/info/?fields=display_name%2Cbio_description%2Cis_verified%2Cfollower_count%2Cfollowing_count%2Clikes_count%2Cvideo_count
[2024-12-17T18:00:30.588+0000] {tiktok_etl.py:168} INFO - Response Content: {"data":{},"error":{"code":"access_token_invalid","message":"The access token is invalid or not found in the request.","log_id":"202412171800294EE2A436D1D7C106C47B"}}
Traceback (most recent call last):
  File "/opt/airflow/dags/tiktok_etl.py", line 147, in tiktok_get_user_info
    response.raise_for_status()  # This will raise an exception for 4xx/5xx errors
    ^^^^^^^^^^^^^^^^^^^^^^^^^^^
  File "/home/airflow/.local/lib/python3.12/site-packages/requests/models.py", line 1024, in raise_for_status
    raise HTTPError(http_error_msg, response=self)
requests.exceptions.HTTPError: 401 Client Error: Unauthorized for url: https://open.tiktokapis.com/v2/research/user/info/?fields=display_name%2Cbio_description%2Cis_verified%2Cfollower_count%2Cfollowing_count%2Clikes_count%2Cvideo_count
[2024-12-17T18:00:30.591+0000] {tiktok_etl.py:169} INFO - Response Headers: {'Server': 'nginx', 'Content-Type': 'application/json', 'Content-Length': '166', 'X-Janus-Info': 'lov8z6fBPtcVOsPCDhlbwxhIJVWrsc_eYQf0nJaSHxy6RUO9lZkiaAemvWWmDI9CszpI85j9bvbZqYnGa5Sj9CO7MNrTLn-mdRyOZu65Xo0p94IDOkUcT3Jq8jW-FvPWCqxXvFo4pGmU_qhDVzXs_YsBepC3rZiDHvwAop7lHeOS7E2DrUwzvRkMbg8PgHuqtg0JVnj_bEod7RrBjwHEvHJxJ7oZ_5BZfFPqURy_oAyVidNdYhKpB930LwbS_PQcu6i6ZG5s_LxiflcVNng8g75otw==', 'X-Tt-Logid': '202412171800294EE2A436D1D7C106C47B', 'x-tt-trace-host': '01e319d294f34508800034e1c707e44b89c1f5e66c2bcbded0de039ac7ea739ef157a9532c6c60351ee39d2862da0e91566452e3ad652e772cf9de478a174aa1503249fc97e3816272b2a31ad7b5d55d8097929e1eb83664bdb7f10d7f405a6a19977c1abe8d38e91932d5409ef71830b0', 'x-tt-trace-id': '00-2412171800294EE2A436D1D7C106C47B-3B998FE96B469CF4-00', 'X-Origin-Response-Time': '26,23.48.249.155', 'Expires': 'Tue, 17 Dec 2024 18:00:29 GMT', 'Cache-Control': 'max-age=0, no-cache, no-store', 'Pragma': 'no-cache', 'Date': 'Tue, 17 Dec 2024 18:00:29 GMT', 'Connection': 'close', 'x-tt-trace-tag': 'id=16;cdn-cache=miss;type=dyn', 'Server-Timing': 'cdn-cache; desc=MISS, edge; dur=112, origin; dur=26, inner; dur=17', 'X-Parent-Response-Time': '135,2.18.41.47'}
Traceback (most recent call last):
  File "/opt/airflow/dags/tiktok_etl.py", line 147, in tiktok_get_user_info
    response.raise_for_status()  # This will raise an exception for 4xx/5xx errors
    ^^^^^^^^^^^^^^^^^^^^^^^^^^^
  File "/home/airflow/.local/lib/python3.12/site-packages/requests/models.py", line 1024, in raise_for_status
    raise HTTPError(http_error_msg, response=self)
requests.exceptions.HTTPError: 401 Client Error: Unauthorized for url: https://open.tiktokapis.com/v2/research/user/info/?fields=display_name%2Cbio_description%2Cis_verified%2Cfollower_count%2Cfollowing_count%2Clikes_count%2Cvideo_count
[2024-12-17T18:00:30.594+0000] {tiktok_dag.py:62} INFO - Successfully fetched data for username: mrbeast
[2024-12-17T18:00:30.595+0000] {tiktok_dag.py:59} INFO - Fetching data for username: jadeanna
[2024-12-17T18:00:30.595+0000] {tiktok_etl.py:134} INFO - Now in function tiktok_get_user_info, getting jadeanna
[2024-12-17T18:00:30.596+0000] {tiktok_etl.py:141} INFO - Requesting TikTok API with URL: https://open.tiktokapis.com/v2/research/user/info/, Headers: {'Authorization': 'Bearer clt.2.2FPqi0MGZIXZZ3clzQTNgyPDqxrcckxt1d-KDYDU4OFr7UMQYh3pHDTym9rRjGwCNZCJ-Oh2yVQv7VAjzbHf8w*0', 'Content-Type': 'application/json'}, Body: {'username': 'jadeanna'}
[2024-12-17T18:00:30.598+0000] {connectionpool.py:1051} DEBUG - Starting new HTTPS connection (1): open.tiktokapis.com:443
[2024-12-17T18:00:30.891+0000] {connectionpool.py:546} DEBUG - https://open.tiktokapis.com:443 "POST /v2/research/user/info/?fields=display_name%2Cbio_description%2Cis_verified%2Cfollower_count%2Cfollowing_count%2Clikes_count%2Cvideo_count HTTP/11" 401 166
[2024-12-17T18:00:30.893+0000] {tiktok_etl.py:144} INFO - Call is done...
[2024-12-17T18:00:30.894+0000] {tiktok_etl.py:164} INFO - TIKTOK request requests.exceptions.HTTPError
[2024-12-17T18:00:30.895+0000] {tiktok_etl.py:166} INFO - HTTP error occurred: 401 Client Error: Unauthorized for url: https://open.tiktokapis.com/v2/research/user/info/?fields=display_name%2Cbio_description%2Cis_verified%2Cfollower_count%2Cfollowing_count%2Clikes_count%2Cvideo_count
Traceback (most recent call last):
  File "/opt/airflow/dags/tiktok_etl.py", line 147, in tiktok_get_user_info
    response.raise_for_status()  # This will raise an exception for 4xx/5xx errors
    ^^^^^^^^^^^^^^^^^^^^^^^^^^^
  File "/home/airflow/.local/lib/python3.12/site-packages/requests/models.py", line 1024, in raise_for_status
    raise HTTPError(http_error_msg, response=self)
requests.exceptions.HTTPError: 401 Client Error: Unauthorized for url: https://open.tiktokapis.com/v2/research/user/info/?fields=display_name%2Cbio_description%2Cis_verified%2Cfollower_count%2Cfollowing_count%2Clikes_count%2Cvideo_count
[2024-12-17T18:00:30.897+0000] {tiktok_etl.py:167} INFO - Status Code: 401
Traceback (most recent call last):
  File "/opt/airflow/dags/tiktok_etl.py", line 147, in tiktok_get_user_info
    response.raise_for_status()  # This will raise an exception for 4xx/5xx errors
    ^^^^^^^^^^^^^^^^^^^^^^^^^^^
  File "/home/airflow/.local/lib/python3.12/site-packages/requests/models.py", line 1024, in raise_for_status
    raise HTTPError(http_error_msg, response=self)
requests.exceptions.HTTPError: 401 Client Error: Unauthorized for url: https://open.tiktokapis.com/v2/research/user/info/?fields=display_name%2Cbio_description%2Cis_verified%2Cfollower_count%2Cfollowing_count%2Clikes_count%2Cvideo_count
[2024-12-17T18:00:30.900+0000] {tiktok_etl.py:168} INFO - Response Content: {"data":{},"error":{"code":"access_token_invalid","message":"The access token is invalid or not found in the request.","log_id":"202412171800294FD7A755B44182094553"}}
Traceback (most recent call last):
  File "/opt/airflow/dags/tiktok_etl.py", line 147, in tiktok_get_user_info
    response.raise_for_status()  # This will raise an exception for 4xx/5xx errors
    ^^^^^^^^^^^^^^^^^^^^^^^^^^^
  File "/home/airflow/.local/lib/python3.12/site-packages/requests/models.py", line 1024, in raise_for_status
    raise HTTPError(http_error_msg, response=self)
requests.exceptions.HTTPError: 401 Client Error: Unauthorized for url: https://open.tiktokapis.com/v2/research/user/info/?fields=display_name%2Cbio_description%2Cis_verified%2Cfollower_count%2Cfollowing_count%2Clikes_count%2Cvideo_count
[2024-12-17T18:00:30.903+0000] {tiktok_etl.py:169} INFO - Response Headers: {'Server': 'nginx', 'Content-Type': 'application/json', 'Content-Length': '166', 'X-Janus-Info': 'NLczWEL5Xo0AYgjsrwaUbhcoVRL_KDsRP_1BDw43K2gaH5TU6QJWsxUpGhsegLlJFfCcLc1dSjGclStkJ6Z2kNaGEHsjey9KCwvICvZGgHExT8uqy5TKUnWdx15ax_PiB4LfHh67Bdkn1vr-zDyYsbfyAwoPVZUdgtpMAd73Wun8Rib7ZUeNbLaa5DqT2n93bkScLHXSg1-RGmDaGP5cYgjuu6xf_Nf4cuVHQF7G8XIpgWi8Xd9ohRROnLSK2YjFDcBc8VVPNaF6bOYV0Yqia0OgOQ==', 'X-Tt-Logid': '202412171800294FD7A755B44182094553', 'x-tt-trace-host': '01e319d294f34508800034e1c707e44b89ba88ab879104adf76f3e433fedc8d14d98ce5f354f44d2fbbd879e99dc8cf3c73a549b234cea4902e218493a03fa3c0175e304df75f5e72582268b3c4a8710f4201f25cb2313a1744c3f725c8aafbf56', 'x-tt-trace-id': '00-2412171800294FD7A755B44182094553-301AA6D9339EC34C-00', 'X-Origin-Response-Time': '22,23.15.7.190', 'Expires': 'Tue, 17 Dec 2024 18:00:29 GMT', 'Cache-Control': 'max-age=0, no-cache, no-store', 'Pragma': 'no-cache', 'Date': 'Tue, 17 Dec 2024 18:00:29 GMT', 'Connection': 'close', 'x-tt-trace-tag': 'id=16;cdn-cache=miss;type=dyn', 'Server-Timing': 'cdn-cache; desc=MISS, edge; dur=154, origin; dur=22, inner; dur=17', 'X-Parent-Response-Time': '172,2.18.41.9'}
Traceback (most recent call last):
  File "/opt/airflow/dags/tiktok_etl.py", line 147, in tiktok_get_user_info
    response.raise_for_status()  # This will raise an exception for 4xx/5xx errors
    ^^^^^^^^^^^^^^^^^^^^^^^^^^^
  File "/home/airflow/.local/lib/python3.12/site-packages/requests/models.py", line 1024, in raise_for_status
    raise HTTPError(http_error_msg, response=self)
requests.exceptions.HTTPError: 401 Client Error: Unauthorized for url: https://open.tiktokapis.com/v2/research/user/info/?fields=display_name%2Cbio_description%2Cis_verified%2Cfollower_count%2Cfollowing_count%2Clikes_count%2Cvideo_count
[2024-12-17T18:00:30.905+0000] {tiktok_dag.py:62} INFO - Successfully fetched data for username: jadeanna
[2024-12-17T18:00:30.906+0000] {tiktok_dag.py:59} INFO - Fetching data for username: feyenoord
[2024-12-17T18:00:30.907+0000] {tiktok_etl.py:134} INFO - Now in function tiktok_get_user_info, getting feyenoord
[2024-12-17T18:00:30.908+0000] {tiktok_etl.py:141} INFO - Requesting TikTok API with URL: https://open.tiktokapis.com/v2/research/user/info/, Headers: {'Authorization': 'Bearer clt.2.2FPqi0MGZIXZZ3clzQTNgyPDqxrcckxt1d-KDYDU4OFr7UMQYh3pHDTym9rRjGwCNZCJ-Oh2yVQv7VAjzbHf8w*0', 'Content-Type': 'application/json'}, Body: {'username': 'feyenoord'}
[2024-12-17T18:00:30.910+0000] {connectionpool.py:1051} DEBUG - Starting new HTTPS connection (1): open.tiktokapis.com:443
[2024-12-17T18:00:31.401+0000] {connectionpool.py:546} DEBUG - https://open.tiktokapis.com:443 "POST /v2/research/user/info/?fields=display_name%2Cbio_description%2Cis_verified%2Cfollower_count%2Cfollowing_count%2Clikes_count%2Cvideo_count HTTP/11" 401 166
[2024-12-17T18:00:31.403+0000] {tiktok_etl.py:144} INFO - Call is done...
[2024-12-17T18:00:31.404+0000] {tiktok_etl.py:164} INFO - TIKTOK request requests.exceptions.HTTPError
[2024-12-17T18:00:31.404+0000] {tiktok_etl.py:166} INFO - HTTP error occurred: 401 Client Error: Unauthorized for url: https://open.tiktokapis.com/v2/research/user/info/?fields=display_name%2Cbio_description%2Cis_verified%2Cfollower_count%2Cfollowing_count%2Clikes_count%2Cvideo_count
Traceback (most recent call last):
  File "/opt/airflow/dags/tiktok_etl.py", line 147, in tiktok_get_user_info
    response.raise_for_status()  # This will raise an exception for 4xx/5xx errors
    ^^^^^^^^^^^^^^^^^^^^^^^^^^^
  File "/home/airflow/.local/lib/python3.12/site-packages/requests/models.py", line 1024, in raise_for_status
    raise HTTPError(http_error_msg, response=self)
requests.exceptions.HTTPError: 401 Client Error: Unauthorized for url: https://open.tiktokapis.com/v2/research/user/info/?fields=display_name%2Cbio_description%2Cis_verified%2Cfollower_count%2Cfollowing_count%2Clikes_count%2Cvideo_count
[2024-12-17T18:00:31.407+0000] {tiktok_etl.py:167} INFO - Status Code: 401
Traceback (most recent call last):
  File "/opt/airflow/dags/tiktok_etl.py", line 147, in tiktok_get_user_info
    response.raise_for_status()  # This will raise an exception for 4xx/5xx errors
    ^^^^^^^^^^^^^^^^^^^^^^^^^^^
  File "/home/airflow/.local/lib/python3.12/site-packages/requests/models.py", line 1024, in raise_for_status
    raise HTTPError(http_error_msg, response=self)
requests.exceptions.HTTPError: 401 Client Error: Unauthorized for url: https://open.tiktokapis.com/v2/research/user/info/?fields=display_name%2Cbio_description%2Cis_verified%2Cfollower_count%2Cfollowing_count%2Clikes_count%2Cvideo_count
[2024-12-17T18:00:31.410+0000] {tiktok_etl.py:168} INFO - Response Content: {"data":{},"error":{"code":"access_token_invalid","message":"The access token is invalid or not found in the request.","log_id":"20241217180030338B4070DB4E8306ACBE"}}
Traceback (most recent call last):
  File "/opt/airflow/dags/tiktok_etl.py", line 147, in tiktok_get_user_info
    response.raise_for_status()  # This will raise an exception for 4xx/5xx errors
    ^^^^^^^^^^^^^^^^^^^^^^^^^^^
  File "/home/airflow/.local/lib/python3.12/site-packages/requests/models.py", line 1024, in raise_for_status
    raise HTTPError(http_error_msg, response=self)
requests.exceptions.HTTPError: 401 Client Error: Unauthorized for url: https://open.tiktokapis.com/v2/research/user/info/?fields=display_name%2Cbio_description%2Cis_verified%2Cfollower_count%2Cfollowing_count%2Clikes_count%2Cvideo_count
[2024-12-17T18:00:31.413+0000] {tiktok_etl.py:169} INFO - Response Headers: {'Server': 'nginx', 'Content-Type': 'application/json', 'Content-Length': '166', 'X-Janus-Info': 'lbClAz8TRI6sNFmrMOz9zoFcha_RH2BuolOzZqfOV_xc9yyUTHjHXxlzyjvQW28iQ9POlv0e9zYrsEva03d3ia_uOkKaiYwwAycZ72cqCRru_3DX9p3A20Itei4K0HHmShezA4PZk4jbbPJAS7EJ4-UVCQnSnkM2JZu6sCjInREAsrL04BY_U01v8B9w-lqEDNZ8i6ACGbtCHqkD9zJ52e-a2mpvGpRZY-14DYrr96l-CMr9k-5ueq4AzwSUyLw-NUmZBNbTbe8utSUMc7os2SGuJA==', 'X-Tt-Logid': '20241217180030338B4070DB4E8306ACBE', 'x-tt-trace-host': '01e319d294f34508800034e1c707e44b89c1f5e66c2bcbded0de039ac7ea739ef157a9532c6c60351ee39d2862da0e915686dd6fd9fe312b8118a54afe706788eb707cfa319118aa4ccf7bfee9cfd42aee098b04504d1ca3b10fc8666b98c7496ea38eb15bbb29beaf44c99625ea6a513c', 'x-tt-trace-id': '00-241217180030338B4070DB4E8306ACBE-6D6C8D44486F6501-00', 'X-Origin-Response-Time': '24,23.48.249.155', 'Expires': 'Tue, 17 Dec 2024 18:00:30 GMT', 'Cache-Control': 'max-age=0, no-cache, no-store', 'Pragma': 'no-cache', 'Date': 'Tue, 17 Dec 2024 18:00:30 GMT', 'Connection': 'close', 'x-tt-trace-tag': 'id=16;cdn-cache=miss;type=dyn', 'Server-Timing': 'cdn-cache; desc=MISS, edge; dur=343, origin; dur=23, inner; dur=13', 'X-Parent-Response-Time': '334,2.18.41.47'}
Traceback (most recent call last):
  File "/opt/airflow/dags/tiktok_etl.py", line 147, in tiktok_get_user_info
    response.raise_for_status()  # This will raise an exception for 4xx/5xx errors
    ^^^^^^^^^^^^^^^^^^^^^^^^^^^
  File "/home/airflow/.local/lib/python3.12/site-packages/requests/models.py", line 1024, in raise_for_status
    raise HTTPError(http_error_msg, response=self)
requests.exceptions.HTTPError: 401 Client Error: Unauthorized for url: https://open.tiktokapis.com/v2/research/user/info/?fields=display_name%2Cbio_description%2Cis_verified%2Cfollower_count%2Cfollowing_count%2Clikes_count%2Cvideo_count
[2024-12-17T18:00:31.415+0000] {tiktok_dag.py:62} INFO - Successfully fetched data for username: feyenoord
[2024-12-17T18:00:31.416+0000] {python.py:240} INFO - Done. Returned value was: None
[2024-12-17T18:00:31.417+0000] {__init__.py:77} DEBUG - Lineage called with inlets: [], outlets: []
[2024-12-17T18:00:31.428+0000] {taskinstance.py:340} INFO - ::group::Post task execution logs
[2024-12-17T18:00:31.429+0000] {taskinstance.py:352} INFO - Marking task as SUCCESS. dag_id=tiktok_dag, task_id=fetch_all_user_data, run_id=manual__2024-12-17T18:00:24.493983+00:00, execution_date=20241217T180024, start_date=20241217T180029, end_date=20241217T180031
[2024-12-17T18:00:31.445+0000] {cli_action_loggers.py:98} DEBUG - Calling callbacks: []
[2024-12-17T18:00:31.487+0000] {local_task_job_runner.py:266} INFO - Task exited with return code 0
[2024-12-17T18:00:31.518+0000] {dagrun.py:968} DEBUG - number of tis tasks for <DagRun tiktok_dag @ 2024-12-17 18:00:24.493983+00:00: manual__2024-12-17T18:00:24.493983+00:00, state:success, queued_at: 2024-12-17 18:00:24.636296+00:00. externally triggered: True>: 2 task(s)
[2024-12-17T18:00:31.519+0000] {taskinstance.py:3895} INFO - 0 downstream tasks scheduled from follow-on schedule check
[2024-12-17T18:00:31.526+0000] {local_task_job_runner.py:245} INFO - ::endgroup::
