[2024-12-17T17:10:58.968+0000] {__init__.py:54} DEBUG - Loading core task runner: StandardTaskRunner
[2024-12-17T17:10:58.995+0000] {base_task_runner.py:73} DEBUG - Planning to run as the  user
[2024-12-17T17:10:59.007+0000] {local_task_job_runner.py:123} INFO - ::group::Pre task execution logs
[2024-12-17T17:10:59.029+0000] {taskinstance.py:2625} DEBUG - <TaskInstance: tiktok_dag.fetch_all_user_data manual__2024-12-17T17:10:54.785410+00:00 [queued]> dependency 'Task Instance State' PASSED: True, Task state queued was valid.
[2024-12-17T17:10:59.030+0000] {taskinstance.py:2625} DEBUG - <TaskInstance: tiktok_dag.fetch_all_user_data manual__2024-12-17T17:10:54.785410+00:00 [queued]> dependency 'Task Instance Not Running' PASSED: True, Task is not in running state.
[2024-12-17T17:10:59.031+0000] {taskinstance.py:2625} DEBUG - <TaskInstance: tiktok_dag.fetch_all_user_data manual__2024-12-17T17:10:54.785410+00:00 [queued]> dependency 'Not In Retry Period' PASSED: True, The task instance was not marked for retrying.
[2024-12-17T17:10:59.032+0000] {taskinstance.py:2625} DEBUG - <TaskInstance: tiktok_dag.fetch_all_user_data manual__2024-12-17T17:10:54.785410+00:00 [queued]> dependency 'Previous Dagrun State' PASSED: True, The task did not have depends_on_past set.
[2024-12-17T17:10:59.033+0000] {taskinstance.py:2613} INFO - Dependencies all met for dep_context=non-requeueable deps ti=<TaskInstance: tiktok_dag.fetch_all_user_data manual__2024-12-17T17:10:54.785410+00:00 [queued]>
[2024-12-17T17:10:59.036+0000] {taskinstance.py:2625} DEBUG - <TaskInstance: tiktok_dag.fetch_all_user_data manual__2024-12-17T17:10:54.785410+00:00 [queued]> dependency 'Not In Retry Period' PASSED: True, The task instance was not marked for retrying.
[2024-12-17T17:10:59.037+0000] {taskinstance.py:2625} DEBUG - <TaskInstance: tiktok_dag.fetch_all_user_data manual__2024-12-17T17:10:54.785410+00:00 [queued]> dependency 'Previous Dagrun State' PASSED: True, The task did not have depends_on_past set.
[2024-12-17T17:10:59.037+0000] {taskinstance.py:2625} DEBUG - <TaskInstance: tiktok_dag.fetch_all_user_data manual__2024-12-17T17:10:54.785410+00:00 [queued]> dependency 'Task Concurrency' PASSED: True, Task concurrency is not set.
[2024-12-17T17:10:59.043+0000] {taskinstance.py:2625} DEBUG - <TaskInstance: tiktok_dag.fetch_all_user_data manual__2024-12-17T17:10:54.785410+00:00 [queued]> dependency 'Pool Slots Available' PASSED: True, There are enough open slots in default_pool to execute the task
[2024-12-17T17:10:59.046+0000] {taskinstance.py:2613} INFO - Dependencies all met for dep_context=requeueable deps ti=<TaskInstance: tiktok_dag.fetch_all_user_data manual__2024-12-17T17:10:54.785410+00:00 [queued]>
[2024-12-17T17:10:59.048+0000] {taskinstance.py:2866} INFO - Starting attempt 1 of 2
[2024-12-17T17:10:59.069+0000] {taskinstance.py:2889} INFO - Executing <Task(PythonOperator): fetch_all_user_data> on 2024-12-17 17:10:54.785410+00:00
[2024-12-17T17:10:59.082+0000] {logging_mixin.py:190} WARNING - /home/***/.local/lib/python3.12/site-packages/***/task/task_runner/standard_task_runner.py:70 DeprecationWarning: This process (pid=571) is multi-threaded, use of fork() may lead to deadlocks in the child.
[2024-12-17T17:10:59.084+0000] {standard_task_runner.py:72} INFO - Started process 577 to run task
[2024-12-17T17:10:59.081+0000] {standard_task_runner.py:104} INFO - Running: ['***', 'tasks', 'run', 'tiktok_dag', 'fetch_all_user_data', 'manual__2024-12-17T17:10:54.785410+00:00', '--job-id', '52', '--raw', '--subdir', 'DAGS_FOLDER/tiktok_dag.py', '--cfg-path', '/tmp/tmp704griub']
[2024-12-17T17:10:59.086+0000] {standard_task_runner.py:105} INFO - Job 52: Subtask fetch_all_user_data
[2024-12-17T17:10:59.087+0000] {cli_action_loggers.py:79} DEBUG - Calling callbacks: [<function default_action_log at 0x7f8722155da0>]
[2024-12-17T17:10:59.213+0000] {task_command.py:467} INFO - Running <TaskInstance: tiktok_dag.fetch_all_user_data manual__2024-12-17T17:10:54.785410+00:00 [running]> on host 8ee198177aea
[2024-12-17T17:10:59.327+0000] {taskinstance.py:2384} DEBUG - Clearing XCom data
[2024-12-17T17:10:59.354+0000] {retries.py:95} DEBUG - Running RenderedTaskInstanceFields.write with retries. Try 1 of 3
[2024-12-17T17:10:59.385+0000] {retries.py:95} DEBUG - Running RenderedTaskInstanceFields._do_delete_old_records with retries. Try 1 of 3
[2024-12-17T17:10:59.426+0000] {taskinstance.py:3132} INFO - Exporting env vars: AIRFLOW_CTX_DAG_OWNER='***' AIRFLOW_CTX_DAG_ID='tiktok_dag' AIRFLOW_CTX_TASK_ID='fetch_all_user_data' AIRFLOW_CTX_EXECUTION_DATE='2024-12-17T17:10:54.785410+00:00' AIRFLOW_CTX_TRY_NUMBER='1' AIRFLOW_CTX_DAG_RUN_ID='manual__2024-12-17T17:10:54.785410+00:00'
[2024-12-17T17:10:59.427+0000] {__init__.py:115} DEBUG - Preparing lineage inlets and outlets
[2024-12-17T17:10:59.433+0000] {__init__.py:154} DEBUG - inlets: [], outlets: []
[2024-12-17T17:10:59.434+0000] {taskinstance.py:731} INFO - ::endgroup::
[2024-12-17T17:10:59.526+0000] {tiktok_dag.py:51} INFO - Fetching data for all usernames...
[2024-12-17T17:10:59.578+0000] {tiktok_dag.py:53} INFO - Usernames pulled from XCom: ['mrbeast', 'jadeanna', 'feyenoord']
[2024-12-17T17:10:59.578+0000] {tiktok_dag.py:59} INFO - Fetching data for username: mrbeast
[2024-12-17T17:10:59.581+0000] {tiktok_etl.py:135} INFO - Now in function tiktok_get_user_info, getting mrbeast
[2024-12-17T17:10:59.582+0000] {tiktok_etl.py:142} INFO - Requesting TikTok API with URL: https://open.tiktokapis.com/v2/research/user/info/, Headers: {'Authorization': 'Bearer clt.2.2FPqi0MGZIXZZ3clzQTNgyPDqxrcckxt1d-KDYDU4OFr7UMQYh3pHDTym9rRjGwCNZCJ-Oh2yVQv7VAjzbHf8w*0', 'Content-Type': 'application/json'}, Body: {'username': 'mrbeast'}
[2024-12-17T17:10:59.587+0000] {connectionpool.py:1051} DEBUG - Starting new HTTPS connection (1): open.tiktokapis.com:443
[2024-12-17T17:11:00.228+0000] {connectionpool.py:546} DEBUG - https://open.tiktokapis.com:443 "POST /v2/research/user/info/?fields=display_name%2Cbio_description%2Cis_verified%2Cfollower_count%2Cfollowing_count%2Clikes_count%2Cvideo_count HTTP/11" 401 166
[2024-12-17T17:11:00.230+0000] {tiktok_etl.py:145} INFO - Call is done...
[2024-12-17T17:11:00.232+0000] {tiktok_etl.py:165} INFO - TIKTOK request requests.exceptions.HTTPError
[2024-12-17T17:11:00.233+0000] {tiktok_etl.py:167} INFO - HTTP error occurred: 401 Client Error: Unauthorized for url: https://open.tiktokapis.com/v2/research/user/info/?fields=display_name%2Cbio_description%2Cis_verified%2Cfollower_count%2Cfollowing_count%2Clikes_count%2Cvideo_count
Traceback (most recent call last):
  File "/opt/airflow/dags/tiktok_etl.py", line 148, in tiktok_get_user_info
    response.raise_for_status()  # This will raise an exception for 4xx/5xx errors
    ^^^^^^^^^^^^^^^^^^^^^^^^^^^
  File "/home/airflow/.local/lib/python3.12/site-packages/requests/models.py", line 1024, in raise_for_status
    raise HTTPError(http_error_msg, response=self)
requests.exceptions.HTTPError: 401 Client Error: Unauthorized for url: https://open.tiktokapis.com/v2/research/user/info/?fields=display_name%2Cbio_description%2Cis_verified%2Cfollower_count%2Cfollowing_count%2Clikes_count%2Cvideo_count
[2024-12-17T17:11:00.240+0000] {tiktok_etl.py:168} INFO - Status Code: 401
Traceback (most recent call last):
  File "/opt/airflow/dags/tiktok_etl.py", line 148, in tiktok_get_user_info
    response.raise_for_status()  # This will raise an exception for 4xx/5xx errors
    ^^^^^^^^^^^^^^^^^^^^^^^^^^^
  File "/home/airflow/.local/lib/python3.12/site-packages/requests/models.py", line 1024, in raise_for_status
    raise HTTPError(http_error_msg, response=self)
requests.exceptions.HTTPError: 401 Client Error: Unauthorized for url: https://open.tiktokapis.com/v2/research/user/info/?fields=display_name%2Cbio_description%2Cis_verified%2Cfollower_count%2Cfollowing_count%2Clikes_count%2Cvideo_count
[2024-12-17T17:11:00.242+0000] {tiktok_etl.py:169} INFO - Response Content: {"data":{},"error":{"code":"access_token_invalid","message":"The access token is invalid or not found in the request.","log_id":"2024121717105921AF355E1F5971077DC0"}}
Traceback (most recent call last):
  File "/opt/airflow/dags/tiktok_etl.py", line 148, in tiktok_get_user_info
    response.raise_for_status()  # This will raise an exception for 4xx/5xx errors
    ^^^^^^^^^^^^^^^^^^^^^^^^^^^
  File "/home/airflow/.local/lib/python3.12/site-packages/requests/models.py", line 1024, in raise_for_status
    raise HTTPError(http_error_msg, response=self)
requests.exceptions.HTTPError: 401 Client Error: Unauthorized for url: https://open.tiktokapis.com/v2/research/user/info/?fields=display_name%2Cbio_description%2Cis_verified%2Cfollower_count%2Cfollowing_count%2Clikes_count%2Cvideo_count
[2024-12-17T17:11:00.245+0000] {tiktok_etl.py:170} INFO - Response Headers: {'Server': 'nginx', 'Content-Type': 'application/json', 'Content-Length': '166', 'X-Janus-Info': '5eTnSBRuHW4jFEDhzIxHBuzMvzzaVSPsQQt4GMyx04KRPtZfVHkh4mcTT1MQIEHwdzkFrv5iOKXvDN9wQ1HvHK3cTzs-qtmqkZ7UJRafK34wRXJbQKFUPyVRK5EXqcNT4vG4KgYFy2tZubnIl_OUGLcHIHZ3unogTYiBjZ8bffIMbO8_X14YyMEtAfQUj7f5K1UfoN0cS0y-VvEWVKceEPZpfP14sIzgoX7tX070_a8pKiYInj4a_dD00VDmnQhQsV74y5kkvqsz0U1J17pfbrcTOQ==', 'X-Tt-Logid': '2024121717105921AF355E1F5971077DC0', 'x-tt-trace-host': '01e319d294f34508800034e1c707e44b890ce23f0810845aeed17d0a43f5d6adf6768dc224c2102e95361362ed02d4385fd292bbfe9a4d2d8b25be18a687b6d96c4c188c79b909380906b10561cc5305d79d60164d7e5bdbce0268408cc7a8b2ea9a614f4f8abd0570bd9c53d17986f235', 'x-tt-trace-id': '00-24121717105921AF355E1F5971077DC0-7AB821AE2CA6BAEE-00', 'X-Origin-Response-Time': '25,23.15.7.190', 'Expires': 'Tue, 17 Dec 2024 17:10:59 GMT', 'Cache-Control': 'max-age=0, no-cache, no-store', 'Pragma': 'no-cache', 'Date': 'Tue, 17 Dec 2024 17:10:59 GMT', 'Connection': 'close', 'x-tt-trace-tag': 'id=16;cdn-cache=miss;type=dyn', 'Server-Timing': 'cdn-cache; desc=MISS, edge; dur=353, origin; dur=25, inner; dur=20', 'X-Parent-Response-Time': '352,2.18.41.139'}
Traceback (most recent call last):
  File "/opt/airflow/dags/tiktok_etl.py", line 148, in tiktok_get_user_info
    response.raise_for_status()  # This will raise an exception for 4xx/5xx errors
    ^^^^^^^^^^^^^^^^^^^^^^^^^^^
  File "/home/airflow/.local/lib/python3.12/site-packages/requests/models.py", line 1024, in raise_for_status
    raise HTTPError(http_error_msg, response=self)
requests.exceptions.HTTPError: 401 Client Error: Unauthorized for url: https://open.tiktokapis.com/v2/research/user/info/?fields=display_name%2Cbio_description%2Cis_verified%2Cfollower_count%2Cfollowing_count%2Clikes_count%2Cvideo_count
[2024-12-17T17:11:00.247+0000] {tiktok_dag.py:62} INFO - Successfully fetched data for username: mrbeast
[2024-12-17T17:11:00.249+0000] {tiktok_dag.py:59} INFO - Fetching data for username: jadeanna
[2024-12-17T17:11:00.249+0000] {tiktok_etl.py:135} INFO - Now in function tiktok_get_user_info, getting jadeanna
[2024-12-17T17:11:00.250+0000] {tiktok_etl.py:142} INFO - Requesting TikTok API with URL: https://open.tiktokapis.com/v2/research/user/info/, Headers: {'Authorization': 'Bearer clt.2.2FPqi0MGZIXZZ3clzQTNgyPDqxrcckxt1d-KDYDU4OFr7UMQYh3pHDTym9rRjGwCNZCJ-Oh2yVQv7VAjzbHf8w*0', 'Content-Type': 'application/json'}, Body: {'username': 'jadeanna'}
[2024-12-17T17:11:00.252+0000] {connectionpool.py:1051} DEBUG - Starting new HTTPS connection (1): open.tiktokapis.com:443
[2024-12-17T17:11:00.791+0000] {connectionpool.py:546} DEBUG - https://open.tiktokapis.com:443 "POST /v2/research/user/info/?fields=display_name%2Cbio_description%2Cis_verified%2Cfollower_count%2Cfollowing_count%2Clikes_count%2Cvideo_count HTTP/11" 401 166
[2024-12-17T17:11:00.792+0000] {tiktok_etl.py:145} INFO - Call is done...
[2024-12-17T17:11:00.793+0000] {tiktok_etl.py:165} INFO - TIKTOK request requests.exceptions.HTTPError
[2024-12-17T17:11:00.793+0000] {tiktok_etl.py:167} INFO - HTTP error occurred: 401 Client Error: Unauthorized for url: https://open.tiktokapis.com/v2/research/user/info/?fields=display_name%2Cbio_description%2Cis_verified%2Cfollower_count%2Cfollowing_count%2Clikes_count%2Cvideo_count
Traceback (most recent call last):
  File "/opt/airflow/dags/tiktok_etl.py", line 148, in tiktok_get_user_info
    response.raise_for_status()  # This will raise an exception for 4xx/5xx errors
    ^^^^^^^^^^^^^^^^^^^^^^^^^^^
  File "/home/airflow/.local/lib/python3.12/site-packages/requests/models.py", line 1024, in raise_for_status
    raise HTTPError(http_error_msg, response=self)
requests.exceptions.HTTPError: 401 Client Error: Unauthorized for url: https://open.tiktokapis.com/v2/research/user/info/?fields=display_name%2Cbio_description%2Cis_verified%2Cfollower_count%2Cfollowing_count%2Clikes_count%2Cvideo_count
[2024-12-17T17:11:00.796+0000] {tiktok_etl.py:168} INFO - Status Code: 401
Traceback (most recent call last):
  File "/opt/airflow/dags/tiktok_etl.py", line 148, in tiktok_get_user_info
    response.raise_for_status()  # This will raise an exception for 4xx/5xx errors
    ^^^^^^^^^^^^^^^^^^^^^^^^^^^
  File "/home/airflow/.local/lib/python3.12/site-packages/requests/models.py", line 1024, in raise_for_status
    raise HTTPError(http_error_msg, response=self)
requests.exceptions.HTTPError: 401 Client Error: Unauthorized for url: https://open.tiktokapis.com/v2/research/user/info/?fields=display_name%2Cbio_description%2Cis_verified%2Cfollower_count%2Cfollowing_count%2Clikes_count%2Cvideo_count
[2024-12-17T17:11:00.799+0000] {tiktok_etl.py:169} INFO - Response Content: {"data":{},"error":{"code":"access_token_invalid","message":"The access token is invalid or not found in the request.","log_id":"20241217171059C63044D4BBDA0B054C3B"}}
Traceback (most recent call last):
  File "/opt/airflow/dags/tiktok_etl.py", line 148, in tiktok_get_user_info
    response.raise_for_status()  # This will raise an exception for 4xx/5xx errors
    ^^^^^^^^^^^^^^^^^^^^^^^^^^^
  File "/home/airflow/.local/lib/python3.12/site-packages/requests/models.py", line 1024, in raise_for_status
    raise HTTPError(http_error_msg, response=self)
requests.exceptions.HTTPError: 401 Client Error: Unauthorized for url: https://open.tiktokapis.com/v2/research/user/info/?fields=display_name%2Cbio_description%2Cis_verified%2Cfollower_count%2Cfollowing_count%2Clikes_count%2Cvideo_count
[2024-12-17T17:11:00.801+0000] {tiktok_etl.py:170} INFO - Response Headers: {'Server': 'nginx', 'Content-Type': 'application/json', 'Content-Length': '166', 'X-Janus-Info': 'GDC5TbVxIIdDm9ceTRAkXgmUtS9UMJUwec2I-bzP3qJVqyoJlH_PIUBmK6a6tZn8Y0okhwMSWiX_oXB6ACRdfiWXE0QjyXolLlWFPcHQLRBszxJ7HBRSbUsgn5ppIzwvAI6nSElQ_ob_S1j2JSA6Oz2_3XJunB-uaBETM-Shnr2wylUDkc5vcRQ6RNV67YyJ3Lqw5-49npozGq0aLVxA9i9OsS2e447J8HsJOhZjGCKByhRZCB6W7czBPut_tAK8Rgj9ENQI343q5V6_qwgq6Sh86Q==', 'X-Tt-Logid': '20241217171059C63044D4BBDA0B054C3B', 'x-tt-trace-host': '01e319d294f34508800034e1c707e44b890ce23f0810845aeed17d0a43f5d6adf6768dc224c2102e95361362ed02d4385f62de2ab9677f8a487b447cae7069c4e53318f15894f4e8afc59e8ca058aa9b2742d6d10680a5f82676389da9f563334f866f6e7379d1101f57d1dcf69c94877d', 'x-tt-trace-id': '00-241217171059C63044D4BBDA0B054C3B-67B5B84D2798D794-00', 'X-Origin-Response-Time': '21,23.15.7.190', 'Expires': 'Tue, 17 Dec 2024 17:10:59 GMT', 'Cache-Control': 'max-age=0, no-cache, no-store', 'Pragma': 'no-cache', 'Date': 'Tue, 17 Dec 2024 17:10:59 GMT', 'Connection': 'close', 'x-tt-trace-tag': 'id=16;cdn-cache=miss;type=dyn', 'Server-Timing': 'cdn-cache; desc=MISS, edge; dur=387, origin; dur=21, inner; dur=16', 'X-Parent-Response-Time': '372,2.18.41.139'}
Traceback (most recent call last):
  File "/opt/airflow/dags/tiktok_etl.py", line 148, in tiktok_get_user_info
    response.raise_for_status()  # This will raise an exception for 4xx/5xx errors
    ^^^^^^^^^^^^^^^^^^^^^^^^^^^
  File "/home/airflow/.local/lib/python3.12/site-packages/requests/models.py", line 1024, in raise_for_status
    raise HTTPError(http_error_msg, response=self)
requests.exceptions.HTTPError: 401 Client Error: Unauthorized for url: https://open.tiktokapis.com/v2/research/user/info/?fields=display_name%2Cbio_description%2Cis_verified%2Cfollower_count%2Cfollowing_count%2Clikes_count%2Cvideo_count
[2024-12-17T17:11:00.804+0000] {tiktok_dag.py:62} INFO - Successfully fetched data for username: jadeanna
[2024-12-17T17:11:00.805+0000] {tiktok_dag.py:59} INFO - Fetching data for username: feyenoord
[2024-12-17T17:11:00.805+0000] {tiktok_etl.py:135} INFO - Now in function tiktok_get_user_info, getting feyenoord
[2024-12-17T17:11:00.806+0000] {tiktok_etl.py:142} INFO - Requesting TikTok API with URL: https://open.tiktokapis.com/v2/research/user/info/, Headers: {'Authorization': 'Bearer clt.2.2FPqi0MGZIXZZ3clzQTNgyPDqxrcckxt1d-KDYDU4OFr7UMQYh3pHDTym9rRjGwCNZCJ-Oh2yVQv7VAjzbHf8w*0', 'Content-Type': 'application/json'}, Body: {'username': 'feyenoord'}
[2024-12-17T17:11:00.807+0000] {connectionpool.py:1051} DEBUG - Starting new HTTPS connection (1): open.tiktokapis.com:443
[2024-12-17T17:11:01.273+0000] {connectionpool.py:546} DEBUG - https://open.tiktokapis.com:443 "POST /v2/research/user/info/?fields=display_name%2Cbio_description%2Cis_verified%2Cfollower_count%2Cfollowing_count%2Clikes_count%2Cvideo_count HTTP/11" 401 166
[2024-12-17T17:11:01.275+0000] {tiktok_etl.py:145} INFO - Call is done...
[2024-12-17T17:11:01.285+0000] {tiktok_etl.py:165} INFO - TIKTOK request requests.exceptions.HTTPError
[2024-12-17T17:11:01.286+0000] {tiktok_etl.py:167} INFO - HTTP error occurred: 401 Client Error: Unauthorized for url: https://open.tiktokapis.com/v2/research/user/info/?fields=display_name%2Cbio_description%2Cis_verified%2Cfollower_count%2Cfollowing_count%2Clikes_count%2Cvideo_count
Traceback (most recent call last):
  File "/opt/airflow/dags/tiktok_etl.py", line 148, in tiktok_get_user_info
    response.raise_for_status()  # This will raise an exception for 4xx/5xx errors
    ^^^^^^^^^^^^^^^^^^^^^^^^^^^
  File "/home/airflow/.local/lib/python3.12/site-packages/requests/models.py", line 1024, in raise_for_status
    raise HTTPError(http_error_msg, response=self)
requests.exceptions.HTTPError: 401 Client Error: Unauthorized for url: https://open.tiktokapis.com/v2/research/user/info/?fields=display_name%2Cbio_description%2Cis_verified%2Cfollower_count%2Cfollowing_count%2Clikes_count%2Cvideo_count
[2024-12-17T17:11:01.288+0000] {tiktok_etl.py:168} INFO - Status Code: 401
Traceback (most recent call last):
  File "/opt/airflow/dags/tiktok_etl.py", line 148, in tiktok_get_user_info
    response.raise_for_status()  # This will raise an exception for 4xx/5xx errors
    ^^^^^^^^^^^^^^^^^^^^^^^^^^^
  File "/home/airflow/.local/lib/python3.12/site-packages/requests/models.py", line 1024, in raise_for_status
    raise HTTPError(http_error_msg, response=self)
requests.exceptions.HTTPError: 401 Client Error: Unauthorized for url: https://open.tiktokapis.com/v2/research/user/info/?fields=display_name%2Cbio_description%2Cis_verified%2Cfollower_count%2Cfollowing_count%2Clikes_count%2Cvideo_count
[2024-12-17T17:11:01.291+0000] {tiktok_etl.py:169} INFO - Response Content: {"data":{},"error":{"code":"access_token_invalid","message":"The access token is invalid or not found in the request.","log_id":"202412171711003CCCDF08BA5177051F45"}}
Traceback (most recent call last):
  File "/opt/airflow/dags/tiktok_etl.py", line 148, in tiktok_get_user_info
    response.raise_for_status()  # This will raise an exception for 4xx/5xx errors
    ^^^^^^^^^^^^^^^^^^^^^^^^^^^
  File "/home/airflow/.local/lib/python3.12/site-packages/requests/models.py", line 1024, in raise_for_status
    raise HTTPError(http_error_msg, response=self)
requests.exceptions.HTTPError: 401 Client Error: Unauthorized for url: https://open.tiktokapis.com/v2/research/user/info/?fields=display_name%2Cbio_description%2Cis_verified%2Cfollower_count%2Cfollowing_count%2Clikes_count%2Cvideo_count
[2024-12-17T17:11:01.293+0000] {tiktok_etl.py:170} INFO - Response Headers: {'Server': 'nginx', 'Content-Type': 'application/json', 'Content-Length': '166', 'X-Janus-Info': 'ezDEgQQ9g_CDQ5mX59ADnOf68t0RKbk2k--sCiM8i3tAP7qWX26S_JJIQGOu_2VCZ5AbVd_mYI08QkTdaB2_15u0dBtdOR2DvvW7BfLjSjTzAx9uJqY2DIAmHzmvO-AfaELiir2DuITXEEqPJ44bMqyYyNkTm8NH-UeTaEE82fxgVnrMq5uxDWPZAjEyXgW_pE-x762euMOCFYvLS2MWDGmdX0LOzh_G1xv1GS7lM5z9N8CafQ16ueu9wXh9p1yWU9HWl-3V1Fm4LpXs0M1VALQSJQ==', 'X-Tt-Logid': '202412171711003CCCDF08BA5177051F45', 'Server-Timing': 'inner; dur=14, cdn-cache; desc=MISS, edge; dur=3, origin; dur=320', 'x-tt-trace-host': '01e319d294f34508800034e1c707e44b89481a0d9836a705de59fb385921a47d9b0a62bf868a356e9d29f06141d32121f29db764342bc9a926bc54b0c0b11a5bba148e565f96d28d367cff56b9a82456d3224bbbce6f6545af6ac18339e10e51f8', 'x-tt-trace-id': '00-2412171711003CCCDF08BA5177051F45-75C64E0F48D369F9-00', 'Expires': 'Tue, 17 Dec 2024 17:11:00 GMT', 'Cache-Control': 'max-age=0, no-cache, no-store', 'Pragma': 'no-cache', 'Date': 'Tue, 17 Dec 2024 17:11:00 GMT', 'Connection': 'close', 'x-tt-trace-tag': 'id=16;cdn-cache=miss;type=dyn', 'X-Origin-Response-Time': '320,2.18.41.194'}
Traceback (most recent call last):
  File "/opt/airflow/dags/tiktok_etl.py", line 148, in tiktok_get_user_info
    response.raise_for_status()  # This will raise an exception for 4xx/5xx errors
    ^^^^^^^^^^^^^^^^^^^^^^^^^^^
  File "/home/airflow/.local/lib/python3.12/site-packages/requests/models.py", line 1024, in raise_for_status
    raise HTTPError(http_error_msg, response=self)
requests.exceptions.HTTPError: 401 Client Error: Unauthorized for url: https://open.tiktokapis.com/v2/research/user/info/?fields=display_name%2Cbio_description%2Cis_verified%2Cfollower_count%2Cfollowing_count%2Clikes_count%2Cvideo_count
[2024-12-17T17:11:01.296+0000] {tiktok_dag.py:62} INFO - Successfully fetched data for username: feyenoord
[2024-12-17T17:11:01.296+0000] {python.py:240} INFO - Done. Returned value was: None
[2024-12-17T17:11:01.298+0000] {__init__.py:77} DEBUG - Lineage called with inlets: [], outlets: []
[2024-12-17T17:11:01.311+0000] {taskinstance.py:340} INFO - ::group::Post task execution logs
[2024-12-17T17:11:01.312+0000] {taskinstance.py:352} INFO - Marking task as SUCCESS. dag_id=tiktok_dag, task_id=fetch_all_user_data, run_id=manual__2024-12-17T17:10:54.785410+00:00, execution_date=20241217T171054, start_date=20241217T171059, end_date=20241217T171101
[2024-12-17T17:11:01.331+0000] {cli_action_loggers.py:98} DEBUG - Calling callbacks: []
[2024-12-17T17:11:01.366+0000] {local_task_job_runner.py:266} INFO - Task exited with return code 0
[2024-12-17T17:11:01.394+0000] {dagrun.py:968} DEBUG - number of tis tasks for <DagRun tiktok_dag @ 2024-12-17 17:10:54.785410+00:00: manual__2024-12-17T17:10:54.785410+00:00, state:running, queued_at: 2024-12-17 17:10:54.801880+00:00. externally triggered: True>: 2 task(s)
[2024-12-17T17:11:01.395+0000] {taskinstance.py:3895} INFO - 0 downstream tasks scheduled from follow-on schedule check
[2024-12-17T17:11:01.401+0000] {local_task_job_runner.py:245} INFO - ::endgroup::
